data/output/CIMB.txt
PASSIVE SELL 1820.00 @ 11.08
PASSIVE BUY 940.00 @ 10.73
PASSIVE SELL 620.00 @ 11.07
PASSIVE BUY 2300.00 @ 10.82
PASSIVE BUY 2780.00 @ 10.97
PASSIVE SELL 860.00 @ 11.14
AGGRESSIVE BUY 2540.00 @ 11.11
PASSIVE BUY 1380.00 @ 11.01
AGGRESSIVE SELL 1460.00 @ 11.01
PASSIVE BUY 1180.00 @ 10.92
PASSIVE BUY 1500.00 @ 10.94
AGGRESSIVE SELL 1180.00 @ 10.98
AGGRESSIVE BUY 1340.00 @ 11.01
PASSIVE BUY 2860.00 @ 11.02
CANCEL BUY 940.00 @ 10.73
CANCEL BUY 2300.00 @ 10.82
CANCEL BUY 2780.00 @ 10.97
CANCEL BUY 1180.00 @ 10.92
CANCEL BUY 1500.00 @ 10.94
CANCEL BUY 180.00 @ 11.01
CANCEL BUY 2860.00 @ 11.02
PASSIVE BUY 900.00 @ 11.03
AGGRESSIVE BUY 1900.00 @ 11.21
AGGRESSIVE SELL 2220.00 @ 11.14
PASSIVE SELL 500.00 @ 11.11
PASSIVE BUY 2020.00 @ 10.93
PASSIVE BUY 2740.00 @ 10.96
PASSIVE SELL 1860.00 @ 11.14
AGGRESSIVE BUY 1060.00 @ 11.14
PASSIVE SELL 1220.00 @ 11.23
PASSIVE BUY 1380.00 @ 10.96
AGGRESSIVE BUY 2260.00 @ 11.14
PASSIVE SELL 1780.00 @ 11.11
PASSIVE SELL 1220.00 @ 11.22
PASSIVE BUY 740.00 @ 11.06
PASSIVE BUY 860.00 @ 11.03
PASSIVE BUY 1180.00 @ 11.06
AGGRESSIVE BUY 740.00 @ 11.11
AGGRESSIVE SELL 1900.00 @ 11.06
PASSIVE SELL 700.00 @ 11.14
AGGRESSIVE SELL 2100.00 @ 11.02
PASSIVE BUY 1260.00 @ 10.88
PASSIVE BUY 2620.00 @ 11.01
AGGRESSIVE SELL 820.00 @ 11.01
PASSIVE SELL 1260.00 @ 11.08
PASSIVE BUY 1820.00 @ 10.96
PASSIVE SELL 2180.00 @ 11.02
PASSIVE SELL 1100.00 @ 11.06
CANCEL SELL 1220.00 @ 11.23
AGGRESSIVE SELL 2300.00 @ 10.96
AGGRESSIVE BUY 1460.00 @ 11.02
AGGRESSIVE BUY 2620.00 @ 11.08
PASSIVE BUY 1820.00 @ 11.02
PASSIVE BUY 1380.00 @ 10.93
AGGRESSIVE SELL 500.00 @ 11.02
AGGRESSIVE SELL 1500.00 @ 10.96
PASSIVE SELL 700.00 @ 11.03
PASSIVE BUY 1860.00 @ 10.95
AGGRESSIVE SELL 1260.00 @ 10.96
AGGRESSIVE BUY 2220.00 @ 11.06
AGGRESSIVE SELL 1380.00 @ 11.06
AGGRESSIVE SELL 1460.00 @ 11.06
AGGRESSIVE SELL 1100.00 @ 10.96
AGGRESSIVE SELL 940.00 @ 10.96
AGGRESSIVE BUY 820.00 @ 11.06
PASSIVE SELL 1460.00 @ 10.97
PASSIVE SELL 1180.00 @ 11.00
CANCEL SELL 1220.00 @ 11.22
PASSIVE BUY 1260.00 @ 10.84
AGGRESSIVE BUY 2180.00 @ 11.00
PASSIVE SELL 540.00 @ 11.08
PASSIVE BUY 1860.00 @ 10.93
PASSIVE SELL 1820.00 @ 11.06
PASSIVE BUY 1860.00 @ 10.93
PASSIVE SELL 1260.00 @ 11.10
PASSIVE SELL 2220.00 @ 11.12
CANCEL SELL -220.00 @ 11.14
CANCEL SELL 700.00 @ 11.14
PASSIVE BUY 2540.00 @ 10.91
AGGRESSIVE SELL 2140.00 @ 10.96
CANCEL SELL 2220.00 @ 11.12
AGGRESSIVE BUY 2180.00 @ 11.06
AGGRESSIVE SELL 1660.00 @ 10.95
PASSIVE SELL 1940.00 @ 11.02
PASSIVE BUY 2700.00 @ 11.01
PASSIVE SELL 900.00 @ 11.12
AGGRESSIVE BUY 1940.00 @ 11.02
PASSIVE BUY 1060.00 @ 10.87
CANCEL BUY -2020.00 @ 10.93
CANCEL BUY 1260.00 @ 10.88
CANCEL BUY -1380.00 @ 10.93
CANCEL BUY 200.00 @ 10.95
CANCEL BUY 1260.00 @ 10.84
CANCEL BUY -1860.00 @ 10.93
CANCEL BUY 1860.00 @ 10.93
CANCEL BUY 2540.00 @ 10.91
CANCEL BUY 2700.00 @ 11.01
CANCEL BUY 1060.00 @ 10.87
PASSIVE SELL 820.00 @ 10.92
PASSIVE SELL 1700.00 @ 10.82
CANCEL SELL 900.00 @ 11.12
AGGRESSIVE BUY 1740.00 @ 10.92
AGGRESSIVE BUY 780.00 @ 10.92
AGGRESSIVE BUY 1580.00 @ 11.08
AGGRESSIVE BUY 1780.00 @ 11.10
PASSIVE SELL 660.00 @ 11.15
PASSIVE SELL 380.00 @ 11.03
AGGRESSIVE BUY 820.00 @ 11.11
PASSIVE SELL 1980.00 @ 11.13
PASSIVE BUY 1500.00 @ 11.07
AGGRESSIVE BUY 2300.00 @ 11.13
AGGRESSIVE BUY 2740.00 @ 11.14
AGGRESSIVE BUY 940.00 @ 11.27
AGGRESSIVE SELL 740.00 @ 11.21
AGGRESSIVE BUY 2340.00 @ 11.28
PASSIVE BUY 780.00 @ 11.20
PASSIVE SELL 1380.00 @ 11.42
PASSIVE SELL 1180.00 @ 11.51
PASSIVE BUY 1500.00 @ 11.18
PASSIVE SELL 1420.00 @ 11.54
PASSIVE BUY 860.00 @ 11.35
PASSIVE SELL 1020.00 @ 11.49
PASSIVE BUY 2180.00 @ 11.30
CANCEL BUY 1500.00 @ 11.07
CANCEL BUY 2460.00 @ 11.14
CANCEL BUY 1880.00 @ 11.28
CANCEL BUY 780.00 @ 11.20
CANCEL BUY 1500.00 @ 11.18
CANCEL BUY 860.00 @ 11.35
CANCEL BUY 2180.00 @ 11.30
PASSIVE SELL 2300.00 @ 11.37
PASSIVE BUY 1940.00 @ 11.34
PASSIVE SELL 1060.00 @ 11.44
AGGRESSIVE BUY 1940.00 @ 11.37
AGGRESSIVE SELL 980.00 @ 11.34
AGGRESSIVE BUY 1180.00 @ 11.37
PASSIVE BUY 1380.00 @ 11.26
PASSIVE BUY 2620.00 @ 11.35
AGGRESSIVE SELL 1660.00 @ 11.35
PASSIVE BUY 1780.00 @ 11.34
PASSIVE SELL 1620.00 @ 11.38
AGGRESSIVE SELL 1940.00 @ 11.34
PASSIVE BUY 2700.00 @ 11.23
PASSIVE BUY 2740.00 @ 11.24
AGGRESSIVE BUY 980.00 @ 11.38
AGGRESSIVE SELL 2260.00 @ 11.34
PASSIVE BUY 1540.00 @ 11.25
AGGRESSIVE BUY 2100.00 @ 11.39
PASSIVE BUY 1420.00 @ 11.24
AGGRESSIVE SELL 1660.00 @ 11.37
PASSIVE BUY 1100.00 @ 11.24
PASSIVE SELL 1860.00 @ 11.35
CANCEL SELL 1420.00 @ 11.54
PASSIVE BUY 1020.00 @ 11.33
AGGRESSIVE BUY 2220.00 @ 11.40
CANCEL BUY 1380.00 @ 11.26
CANCEL BUY 320.00 @ 11.34
CANCEL BUY 2700.00 @ 11.23
CANCEL BUY -2740.00 @ 11.24
CANCEL BUY 1540.00 @ 11.25
CANCEL BUY -1420.00 @ 11.24
CANCEL BUY 1100.00 @ 11.24
CANCEL BUY 1020.00 @ 11.33
CANCEL BUY 160.00 @ 11.40
PASSIVE SELL 1740.00 @ 11.36
PASSIVE BUY 2180.00 @ 11.33
AGGRESSIVE BUY 2380.00 @ 11.42
PASSIVE SELL 620.00 @ 11.34
AGGRESSIVE SELL 900.00 @ 11.33
PASSIVE BUY 1220.00 @ 11.27
PASSIVE BUY 1620.00 @ 11.32
AGGRESSIVE BUY 1420.00 @ 11.37
PASSIVE SELL 1540.00 @ 11.41
AGGRESSIVE BUY 2580.00 @ 11.44
PASSIVE BUY 2140.00 @ 11.25
PASSIVE SELL 820.00 @ 11.51
AGGRESSIVE BUY 1820.00 @ 11.47
PASSIVE SELL 1340.00 @ 11.49
PASSIVE SELL 2060.00 @ 11.60
PASSIVE BUY 2300.00 @ 11.34
CANCEL BUY 1280.00 @ 11.33
CANCEL BUY 1220.00 @ 11.27
CANCEL BUY 1620.00 @ 11.32
CANCEL BUY 800.00 @ 11.37
CANCEL BUY 2140.00 @ 11.25
CANCEL BUY 1060.00 @ 11.47
CANCEL BUY 2300.00 @ 11.34
PASSIVE SELL 2140.00 @ 11.50
AGGRESSIVE BUY 1620.00 @ 11.49
AGGRESSIVE BUY 940.00 @ 11.50
PASSIVE BUY 2220.00 @ 11.32
PASSIVE BUY 1460.00 @ 11.38
PASSIVE SELL 2180.00 @ 11.44
PASSIVE SELL 740.00 @ 11.49
PASSIVE BUY 940.00 @ 11.27
PASSIVE SELL 2220.00 @ 11.44
PASSIVE SELL 1060.00 @ 11.52
AGGRESSIVE BUY 2900.00 @ 11.44
PASSIVE SELL 1460.00 @ 11.46
CANCEL SELL 2060.00 @ 11.60
AGGRESSIVE SELL 1620.00 @ 11.32
PASSIVE BUY 2060.00 @ 11.25
PASSIVE SELL 1900.00 @ 11.37
CANCEL SELL 1060.00 @ 11.52
AGGRESSIVE BUY 940.00 @ 11.37
AGGRESSIVE BUY 2460.00 @ 11.44
PASSIVE BUY 2340.00 @ 11.26
PASSIVE SELL 420.00 @ 11.47
PASSIVE SELL 780.00 @ 11.48
AGGRESSIVE SELL 1460.00 @ 11.32
PASSIVE SELL 1260.00 @ 11.33
CANCEL SELL -1180.00 @ 11.51
CANCEL SELL 820.00 @ 11.51
AGGRESSIVE SELL 1060.00 @ 11.28
CANCEL SELL 1940.00 @ 11.50
AGGRESSIVE BUY 740.00 @ 11.33
AGGRESSIVE SELL 2100.00 @ 11.26
AGGRESSIVE BUY 940.00 @ 11.33
PASSIVE SELL 1900.00 @ 11.36
PASSIVE BUY 860.00 @ 11.22
PASSIVE BUY 860.00 @ 11.15
AGGRESSIVE SELL 1620.00 @ 11.25
PASSIVE SELL 660.00 @ 11.35
CANCEL SELL 740.00 @ 11.49
PASSIVE BUY 2500.00 @ 11.15
AGGRESSIVE BUY 2060.00 @ 11.33
PASSIVE BUY 2940.00 @ 11.29
AGGRESSIVE SELL 1860.00 @ 11.33
PASSIVE SELL 660.00 @ 11.47
PASSIVE SELL 1300.00 @ 11.36
AGGRESSIVE BUY 2420.00 @ 11.36
PASSIVE BUY 2540.00 @ 11.22
PASSIVE BUY 2340.00 @ 11.29
PASSIVE BUY 1260.00 @ 11.22
PASSIVE BUY 1020.00 @ 11.31
PASSIVE SELL 1820.00 @ 11.46
AGGRESSIVE BUY 1580.00 @ 11.46
PASSIVE SELL 1900.00 @ 11.55
PASSIVE BUY 2020.00 @ 11.45
CANCEL BUY 1620.00 @ 11.25
CANCEL BUY -860.00 @ 11.22
CANCEL BUY -860.00 @ 11.15
CANCEL BUY 2500.00 @ 11.15
CANCEL BUY 160.00 @ 11.33
CANCEL BUY -2940.00 @ 11.29
CANCEL BUY -2540.00 @ 11.22
CANCEL BUY 2340.00 @ 11.29
CANCEL BUY 1260.00 @ 11.22
CANCEL BUY 1020.00 @ 11.31
CANCEL BUY 2020.00 @ 11.45
PASSIVE SELL 2260.00 @ 11.46
PASSIVE BUY 2380.00 @ 11.43
PASSIVE SELL 860.00 @ 11.46
PASSIVE SELL 1820.00 @ 11.48
PASSIVE BUY 1020.00 @ 11.36
AGGRESSIVE SELL 2140.00 @ 11.43
PASSIVE BUY 2180.00 @ 11.43
PASSIVE BUY 2420.00 @ 11.33
AGGRESSIVE BUY 1540.00 @ 11.46
PASSIVE SELL 1860.00 @ 11.50
PASSIVE BUY 1580.00 @ 11.42
PASSIVE BUY 1900.00 @ 11.38
PASSIVE BUY 1140.00 @ 11.39
AGGRESSIVE SELL 900.00 @ 11.43
AGGRESSIVE BUY 1980.00 @ 11.46
AGGRESSIVE BUY 2580.00 @ 11.46
PASSIVE BUY 1180.00 @ 11.37
CANCEL BUY 1020.00 @ 11.36
CANCEL BUY 1520.00 @ 11.43
CANCEL BUY 2420.00 @ 11.33
CANCEL BUY 1580.00 @ 11.42
CANCEL BUY 1900.00 @ 11.38
CANCEL BUY 1140.00 @ 11.39
CANCEL BUY 1180.00 @ 11.37
PASSIVE SELL 1740.00 @ 11.35
PASSIVE SELL 620.00 @ 11.27
CANCEL SELL 1900.00 @ 11.55
AGGRESSIVE BUY 1300.00 @ 11.35
PASSIVE SELL 580.00 @ 11.26
