data/output/EPMB.txt
PASSIVE SELL 1700.00 @ 719.17
PASSIVE SELL 620.00 @ 719.10
PASSIVE SELL 500.00 @ 719.04
PASSIVE BUY 2140.00 @ 718.69
PASSIVE BUY 1860.00 @ 718.85
PASSIVE SELL 2020.00 @ 718.96
PASSIVE SELL 1940.00 @ 718.97
PASSIVE SELL 1340.00 @ 719.04
PASSIVE SELL 1340.00 @ 719.03
PASSIVE BUY 2540.00 @ 718.86
PASSIVE BUY 2820.00 @ 718.88
AGGRESSIVE BUY 1660.00 @ 718.96
PASSIVE SELL 1860.00 @ 719.08
CANCEL SELL 1700.00 @ 719.17
PASSIVE BUY 2820.00 @ 718.90
AGGRESSIVE SELL 1940.00 @ 718.90
PASSIVE SELL 780.00 @ 718.97
AGGRESSIVE SELL 380.00 @ 718.90
PASSIVE BUY 780.00 @ 718.95
AGGRESSIVE SELL 1740.00 @ 718.88
PASSIVE SELL 1660.00 @ 718.95
CANCEL SELL 620.00 @ 719.10
PASSIVE SELL 1700.00 @ 718.91
CANCEL SELL 1860.00 @ 719.08
PASSIVE SELL 620.00 @ 719.02
CANCEL SELL -500.00 @ 719.04
CANCEL SELL 1340.00 @ 719.04
AGGRESSIVE SELL 420.00 @ 718.88
AGGRESSIVE SELL 700.00 @ 718.88
PASSIVE SELL 1180.00 @ 718.94
CANCEL SELL 1340.00 @ 719.03
AGGRESSIVE BUY 2020.00 @ 718.94
AGGRESSIVE SELL 1540.00 @ 718.86
AGGRESSIVE BUY 1220.00 @ 718.95
PASSIVE BUY 2540.00 @ 718.92
PASSIVE SELL 1060.00 @ 719.03
PASSIVE SELL 500.00 @ 719.05
AGGRESSIVE BUY 2340.00 @ 718.97
AGGRESSIVE BUY 940.00 @ 718.97
PASSIVE BUY 2500.00 @ 718.96
AGGRESSIVE SELL 700.00 @ 718.96
AGGRESSIVE BUY 2020.00 @ 719.03
PASSIVE SELL 1660.00 @ 719.04
PASSIVE SELL 540.00 @ 719.00
PASSIVE SELL 940.00 @ 718.98
AGGRESSIVE SELL 2100.00 @ 718.95
AGGRESSIVE BUY 2300.00 @ 719.03
AGGRESSIVE SELL 1300.00 @ 718.92
AGGRESSIVE SELL 1260.00 @ 718.86
PASSIVE SELL 420.00 @ 718.88
PASSIVE SELL 1060.00 @ 718.97
AGGRESSIVE SELL 460.00 @ 718.86
PASSIVE BUY 860.00 @ 718.83
PASSIVE SELL 700.00 @ 718.88
PASSIVE SELL 1780.00 @ 718.93
PASSIVE SELL 580.00 @ 718.96
CANCEL SELL 500.00 @ 719.05
PASSIVE BUY 2220.00 @ 718.83
AGGRESSIVE BUY 1140.00 @ 718.93
PASSIVE SELL 1500.00 @ 719.05
PASSIVE SELL 1860.00 @ 718.87
CANCEL SELL 1500.00 @ 719.05
AGGRESSIVE SELL 940.00 @ 718.86
PASSIVE SELL 1260.00 @ 718.87
PASSIVE BUY 2260.00 @ 718.84
PASSIVE BUY 1660.00 @ 718.83
AGGRESSIVE SELL 460.00 @ 718.86
PASSIVE BUY 1700.00 @ 718.82
AGGRESSIVE BUY 1100.00 @ 718.87
PASSIVE BUY 2180.00 @ 718.84
AGGRESSIVE BUY 1940.00 @ 718.87
AGGRESSIVE SELL 1500.00 @ 718.85
AGGRESSIVE SELL 1100.00 @ 718.84
PASSIVE SELL 1420.00 @ 718.91
CANCEL SELL 1660.00 @ 719.04
PASSIVE BUY 1940.00 @ 718.74
PASSIVE SELL 2140.00 @ 719.02
CANCEL SELL 240.00 @ 719.03
AGGRESSIVE BUY 1740.00 @ 718.91
AGGRESSIVE SELL 1180.00 @ 718.89
AGGRESSIVE SELL 2260.00 @ 718.84
AGGRESSIVE SELL 460.00 @ 718.84
PASSIVE BUY 2300.00 @ 718.85
AGGRESSIVE SELL 1500.00 @ 718.85
AGGRESSIVE BUY 1700.00 @ 718.89
CANCEL BUY 2140.00 @ 718.69
CANCEL BUY -860.00 @ 718.83
CANCEL BUY -2220.00 @ 718.83
CANCEL BUY 1660.00 @ 718.83
CANCEL BUY 1700.00 @ 718.82
CANCEL BUY 1340.00 @ 718.84
CANCEL BUY 1940.00 @ 718.74
CANCEL BUY 800.00 @ 718.85
CANCEL BUY 760.00 @ 718.89
PASSIVE SELL 1460.00 @ 718.82
AGGRESSIVE BUY 2020.00 @ 718.82
PASSIVE BUY 2780.00 @ 718.83
PASSIVE BUY 1460.00 @ 718.90
AGGRESSIVE SELL 2300.00 @ 718.90
PASSIVE BUY 2020.00 @ 718.84
AGGRESSIVE SELL 380.00 @ 718.84
AGGRESSIVE SELL 2060.00 @ 718.83
PASSIVE BUY 1540.00 @ 718.82
PASSIVE BUY 740.00 @ 718.73
AGGRESSIVE BUY 1460.00 @ 718.93
PASSIVE SELL 1300.00 @ 719.04
PASSIVE BUY 1580.00 @ 718.87
AGGRESSIVE BUY 2780.00 @ 718.97
PASSIVE BUY 2140.00 @ 718.90
PASSIVE BUY 820.00 @ 718.98
AGGRESSIVE BUY 1700.00 @ 719.02
PASSIVE BUY 1620.00 @ 718.91
CANCEL BUY -560.00 @ 718.82
CANCEL BUY 2360.00 @ 718.83
CANCEL BUY 1540.00 @ 718.82
CANCEL BUY 740.00 @ 718.73
CANCEL BUY 1580.00 @ 718.87
CANCEL BUY 2140.00 @ 718.90
CANCEL BUY 820.00 @ 718.98
CANCEL BUY 1620.00 @ 718.91
PASSIVE BUY 1860.00 @ 719.00
AGGRESSIVE SELL 1540.00 @ 719.00
PASSIVE SELL 1860.00 @ 719.05
PASSIVE BUY 1380.00 @ 718.94
AGGRESSIVE SELL 540.00 @ 718.94
PASSIVE BUY 2900.00 @ 718.88
AGGRESSIVE SELL 940.00 @ 718.94
AGGRESSIVE BUY 1980.00 @ 719.05
PASSIVE BUY 1900.00 @ 718.89
PASSIVE SELL 420.00 @ 719.05
PASSIVE SELL 660.00 @ 719.11
PASSIVE BUY 780.00 @ 718.90
PASSIVE BUY 2820.00 @ 719.01
PASSIVE BUY 1660.00 @ 718.93
AGGRESSIVE BUY 1140.00 @ 719.05
PASSIVE BUY 1420.00 @ 718.95
CANCEL BUY 220.00 @ 718.94
CANCEL BUY 2900.00 @ 718.88
CANCEL BUY 1900.00 @ 718.89
CANCEL BUY 780.00 @ 718.90
CANCEL BUY 2820.00 @ 719.01
CANCEL BUY 1660.00 @ 718.93
CANCEL BUY 1420.00 @ 718.95
PASSIVE SELL 2140.00 @ 719.12
PASSIVE SELL 740.00 @ 719.16
PASSIVE BUY 2060.00 @ 719.00
AGGRESSIVE BUY 2420.00 @ 719.12
PASSIVE BUY 1780.00 @ 718.90
AGGRESSIVE SELL 620.00 @ 719.00
PASSIVE SELL 780.00 @ 719.07
AGGRESSIVE SELL 2100.00 @ 718.92
AGGRESSIVE SELL 940.00 @ 718.90
PASSIVE SELL 780.00 @ 718.99
AGGRESSIVE SELL 780.00 @ 718.90
AGGRESSIVE SELL 1460.00 @ 718.90
PASSIVE BUY 1620.00 @ 718.78
PASSIVE BUY 1380.00 @ 718.81
PASSIVE BUY 1260.00 @ 718.74
AGGRESSIVE SELL 1420.00 @ 718.78
PASSIVE SELL 1740.00 @ 718.84
CANCEL SELL 740.00 @ 719.16
PASSIVE BUY 1780.00 @ 718.82
PASSIVE SELL 2140.00 @ 718.94
CANCEL SELL 1280.00 @ 719.12
AGGRESSIVE SELL 1660.00 @ 718.82
AGGRESSIVE SELL 660.00 @ 718.78
PASSIVE SELL 500.00 @ 718.85
CANCEL SELL 780.00 @ 719.07
PASSIVE SELL 1940.00 @ 718.87
CANCEL SELL 780.00 @ 718.99
PASSIVE SELL 1300.00 @ 718.86
CANCEL SELL 2140.00 @ 718.94
AGGRESSIVE SELL 2060.00 @ 718.77
CANCEL SELL 660.00 @ 718.92
AGGRESSIVE SELL 1300.00 @ 718.74
CANCEL SELL 1400.00 @ 718.90
PASSIVE SELL 1020.00 @ 718.67
CANCEL SELL 1940.00 @ 718.87
PASSIVE SELL 860.00 @ 718.79
CANCEL SELL 1300.00 @ 718.86
PASSIVE SELL 580.00 @ 718.58
CANCEL SELL 500.00 @ 718.85
PASSIVE SELL 1180.00 @ 718.45
CANCEL SELL 1740.00 @ 718.84
AGGRESSIVE BUY 2740.00 @ 718.67
AGGRESSIVE BUY 1860.00 @ 718.79
PASSIVE BUY 940.00 @ 718.62
PASSIVE SELL 1220.00 @ 718.79
PASSIVE SELL 380.00 @ 718.78
PASSIVE BUY 2780.00 @ 718.58
PASSIVE SELL 1620.00 @ 718.78
PASSIVE BUY 2140.00 @ 718.71
PASSIVE SELL 1340.00 @ 718.80
PASSIVE BUY 1700.00 @ 718.60
PASSIVE SELL 540.00 @ 718.85
PASSIVE SELL 900.00 @ 718.80
AGGRESSIVE SELL 620.00 @ 718.71
PASSIVE SELL 700.00 @ 718.82
AGGRESSIVE SELL 860.00 @ 718.71
AGGRESSIVE SELL 1220.00 @ 718.63
AGGRESSIVE BUY 1860.00 @ 718.72
PASSIVE BUY 2700.00 @ 718.69
AGGRESSIVE BUY 1180.00 @ 718.78
AGGRESSIVE BUY 1820.00 @ 718.78
PASSIVE SELL 420.00 @ 718.80
PASSIVE BUY 2260.00 @ 718.73
CANCEL BUY 940.00 @ 718.62
CANCEL BUY 2780.00 @ 718.58
CANCEL BUY 1700.00 @ 718.60
CANCEL BUY 1300.00 @ 718.72
CANCEL BUY 2700.00 @ 718.69
CANCEL BUY 1000.00 @ 718.78
CANCEL BUY 2260.00 @ 718.73
PASSIVE SELL 420.00 @ 718.76
PASSIVE BUY 2500.00 @ 718.70
AGGRESSIVE BUY 1180.00 @ 718.79
PASSIVE SELL 380.00 @ 718.88
PASSIVE BUY 2340.00 @ 718.76
AGGRESSIVE BUY 2300.00 @ 718.80
PASSIVE SELL 660.00 @ 718.84
AGGRESSIVE BUY 1860.00 @ 718.84
PASSIVE SELL 1620.00 @ 718.91
PASSIVE SELL 1020.00 @ 718.91
PASSIVE BUY 2460.00 @ 718.69
PASSIVE SELL 1020.00 @ 718.91
PASSIVE SELL 2020.00 @ 718.85
AGGRESSIVE BUY 820.00 @ 718.85
AGGRESSIVE BUY 860.00 @ 718.85
PASSIVE SELL 980.00 @ 718.84
PASSIVE SELL 1140.00 @ 718.87
AGGRESSIVE SELL 1740.00 @ 718.76
PASSIVE BUY 2860.00 @ 718.81
AGGRESSIVE SELL 980.00 @ 718.81
AGGRESSIVE SELL 2060.00 @ 718.76
PASSIVE SELL 380.00 @ 718.93
PASSIVE SELL 1900.00 @ 718.86
CANCEL SELL 380.00 @ 718.93
PASSIVE SELL 1980.00 @ 718.77
CANCEL SELL -1620.00 @ 718.91
CANCEL SELL -1020.00 @ 718.91
CANCEL SELL 1020.00 @ 718.91
AGGRESSIVE BUY 2300.00 @ 718.84
AGGRESSIVE SELL 1460.00 @ 718.76
PASSIVE BUY 2220.00 @ 718.67
PASSIVE SELL 820.00 @ 718.75
CANCEL SELL 380.00 @ 718.88
PASSIVE SELL 860.00 @ 718.82
CANCEL SELL 1140.00 @ 718.87
PASSIVE SELL 1460.00 @ 718.73
CANCEL SELL 1900.00 @ 718.86
AGGRESSIVE BUY 2780.00 @ 718.75
AGGRESSIVE SELL 1300.00 @ 718.74
AGGRESSIVE BUY 2340.00 @ 718.76
PASSIVE SELL 2100.00 @ 718.89
AGGRESSIVE SELL 2020.00 @ 718.70
PASSIVE SELL 380.00 @ 718.88
PASSIVE BUY 2940.00 @ 718.77
PASSIVE SELL 2260.00 @ 718.91
PASSIVE BUY 1020.00 @ 718.80
AGGRESSIVE BUY 2620.00 @ 718.85
PASSIVE BUY 1340.00 @ 718.72
AGGRESSIVE SELL 2140.00 @ 718.77
PASSIVE BUY 1580.00 @ 718.78
AGGRESSIVE SELL 1620.00 @ 718.77
AGGRESSIVE BUY 2260.00 @ 718.89
AGGRESSIVE BUY 2940.00 @ 718.93
PASSIVE SELL 1260.00 @ 718.95
